Workbook

Sheet Puebla
A1: Puebla: población total censada por sexo y grupos quinquenales de edad, 2010 | F1: Puebla: población total censada por sexo y grupos quinquenales de edad, 2019 | L1: Puebla: nacimientos por grupos quinquenales de edad de la madre, 2010
L3: Edad | M3: Puebla 2010 | N3: Población 30/06/2010 | P3: Puebla: nacimientos por sexo, 2010
L4: 15-19 | M4: 14203 | N4: 307908.78
A5: Edad | B5: Puebla 2010 | F5: Edad | G5: Puebla 2019 | L5: 20-24 | M5: 23995 | N5: 273081.32 | P5: Hombres | Q5: Mujeres | R5: Total
B6: Hombres | C6: Mujeres | D6: Total | G6: Hombres | H6: Mujeres | I6: Total | L6: 25-29 | M6: 20094 | N6: 240204.31 | P6: 41132 | Q6: =39110 -> 39110 | R6: 80299
A7: 0-4 | B7: =54889 + 239158 -> 294047 | C7: =52963+232162 -> 285125 | D7: =107852+471309 -> 579161 | F7: 0-4 | G7: =63812+62704 -> 126516 | H7: =61523+60517 -> 122040 | I7: =G7+H7 -> 248556 | L7: 30-34 | M7: 13457 | N7: 229716.09
A8: 5-9 | B8: 317391.35 | C8: 309188.89 | D8: 626565.4 | F8: 5-9 | G8: 313806 | H8: 303890 | I8: =G8+H8 -> 617696 | L8: 35-39 | M8: 6257 | N8: 214298.24 | P8: K | Q8: =Q6/R6 -> 0.48705463
A9: 10-14 | B9: 308838.24 | C9: 302045.32 | D9: 610869.61 | F9: 10-14 | G9: 318723 | H9: 311088 | I9: =G9+H9 -> 629811 | L9: 40-44 | M9: 1432 | N9: 179021.52
A10: 15-19 | B10: 302210.98 | C10: 307908.78 | D10: 610111.13 | F10: 15-19 | G10: 317441 | H10: 314520 | I10: =G10+H10 -> 631961 | L10: 45-49 | M10: 131 | N10: 151550.65
A11: 20-24 | B11: 243697.25 | C11: 273081.32 | D11: 516781.68 | F11: 20-24 | G11: 302389 | H11: 305706 | I11: =G11+H11 -> 608095 | L11: Total | M11: =SUM(M4:M10) -> 79569 | N11: =SUM(N4:N10) -> 1595780.9
A12: 25-29 | B12: 205745.32 | C12: 240204.31 | D12: 445956.17 | F12: 25-29 | G12: 277285 | H12: 291099 | I12: =G12+H12 -> 568384 | L12: Fuente: Elaborado sobre la base de estadísticas vitales
A13: 30-34 | B13: 194957.19 | C13: 229716.09 | D13: 424680.34 | F13: 30-34 | G13: 234851 | H13: 262743 | I13: =G13+H13 -> 497594
A14: 35-39 | B14: 184591.42 | C14: 214298.24 | D14: 398895.04 | F14: 35-39 | G14: 195551 | H14: 238652 | I14: =G14+H14 -> 434203 | K14: Tasas de crecimiento exponencial para Edades Específicas MEF
A15: 40-44 | B15: 152801.96 | C15: 179021.52 | D15: 331828.61 | F15: 40-44 | G15: 178592 | H15: 221454 | I15: =G15+H15 -> 400046 | K15: 15-19
A16: 45-49 | B16: 130653.82 | C16: 151550.65 | D16: 282208.24 | F16: 45-49 | G16: 168120 | H16: 200458 | I16: =G16+H16 -> 368578 | K16: Fechas | L16: ti | M16: N | N16: r | P16: ti | Q16: Δt | R16: N30/06/2010
A17: 50-54 | B17: 111525.79 | C17: 130881.12 | D17: 242410.74 | F17: 50-54 | G17: 145806 | H17: 169598 | I17: =G17+H17 -> 315404 | K17: 40186 | L17: =2010+7/12+1/365 -> 2010.5861 | M17: =C10 -> 307908.78 | N17: =LN(M18/M17)/L19 -> 0.0023390924 | P17: =2010+6/12+0/365 -> 2010.5 | Q17: =P17-L17 -> -0.086073059 | R17: =M17*EXP($N$17*Q17) -> 307846.8
A18: 55-59 | B18: 89125.049 | C18: 101673.82 | D18: 190800.74 | F18: 55-59 | G18: 122143 | H18: 141335 | I18: =G18+H18 -> 263478 | K18: 43708 | L18: =2019+7/12+31/365 -> 2019.6683 | M18: =H10 -> 314520
A19: 60-64 | B19: 69759.571 | C19: 82302.573 | D19: 152064.71 | F19: 60-64 | G19: 96456 | H19: 112369 | I19: =G19+H19 -> 208825 | K19: Δt | L19: =L18-L17 -> 9.0821918
A20: 65-69 | B20: 53939.615 | C20: 63203.902 | D20: 117145.33 | F20: 65-69 | G20: 71907 | H20: 85111 | I20: =G20+H20 -> 157018
A21: 70-74 | B21: 43859.786 | C21: 53785.808 | D21: 97648.039 | F21: 70-74 | G21: 55098 | H21: 66369 | I21: =G21+H21 -> 121467 | K21: 20-24
A22: 75-79 | B22: 30552.714 | C22: 37132.267 | D22: 67686.548 | F22: 75-79 | G22: 39389 | H22: 48885 | I22: =G22+H22 -> 88274 | K22: Fechas | L22: ti | M22: N | N22: r | P22: ti | Q22: Δt | R22: N30/06/2010
A23: 80-84 | B23: 19166.427 | C23: 24631.007 | D23: 43798.961 | F23: 80-84 | G23: 25268 | H23: 32500 | I23: =G23+H23 -> 57768 | K23: =K17 -> 40186 | L23: =L17 -> 2010.5861 | M23: =C11 -> 273081.32 | N23: =LN(M24/M23)/L25 -> 0.012425881 | P23: =P17 -> 2010.5 | Q23: =P23-L23 -> -0.086073059 | R23: =M23*EXP($N$23*Q23) -> 272789.41
A24: 85-89 | B24: 16991.019 | C24: 24223.148 | D24: 41216.491 | F24: 85-89 | G24: 23086 | H24: 30499 | I24: =G24+H24 -> 53585 | K24: =K18 -> 43708 | L24: =L18 -> 2019.6683 | M24: =H11 -> 305706
K25: Δt | L25: =L24-L23 -> 9.0821918
A26: Total | B26: =SUM(B7:B25) -> 2769854.5 | C26: =SUM(C7:C25) -> 3009973.8 | D26: =SUM(D7:D25) -> 5779828.8 | F26: Total | G26: =SUM(G7:G24) -> 3012427 | H26: =SUM(H7:H24) -> 3258316 | I26: =SUM(I7:I24) -> 6270743
K27: 25-29
K28: Fechas | L28: ti | M28: N | N28: r | P28: ti | Q28: Δt | R28: N30/06/2010
A29: Tasas de crecimiento exponencial para el Total de la Población | K29: =K23 -> 40186 | L29: =L23 -> 2010.5861 | M29: =C12 -> 240204.31 | N29: =LN(M30/M29)/L31 -> 0.021159383 | P29: =P23 -> 2010.5 | Q29: =P29-L29 -> -0.086073059 | R29: =M29*EXP($N$29*Q29) -> 239767.23
A30: 15-19 | K30: =K24 -> 43708 | L30: =L24 -> 2019.6683 | M30: =H12 -> 291099
A31: Fechas | B31: ti | C31: N | D31: r | F31: ti | G31: Δt | H31: N30/06/2010 | K31: Δt | L31: =L30-L29 -> 9.0821918
A32: 36533 | B32: =2000+7/12+1/365 -> 2000.5861 | C32: =D26 -> 5779828.8 | D32: =LN(C33/C32)/B34 -> 0.0080856216 | F32: =2010+6/12+0/365 -> 2010.5 | G32: =F32-B32 -> 9.9139269 | H32: =C32*EXP($D$32*G32) -> 6262217.3
A33: 31/08/2010 | B33: =2010+7/12+31/365 -> 2010.6683 | C33: =I26 -> 6270743 | K33: 30-34
A34: Δt | B34: =B33-B32 -> 10.082192 | K34: Fechas | L34: ti | M34: N | N34: r | P34: ti | Q34: Δt | R34: N30/06/2010
K35: =K29 -> 40186 | L35: =L29 -> 2010.5861 | M35: =C13 -> 229716.09 | N35: =LN(M36/M35)/L37 -> 0.014790727 | P35: =P29 -> 2010.5 | Q35: =P35-L35 -> -0.086073059 | R35: =M35*EXP($N$35*Q35) -> 229423.83
K36: =K30 -> 43708 | L36: =L30 -> 2019.6683 | M36: =H13 -> 262743
K37: Δt | L37: =L36-L35 -> 9.0821918
K39: 35-39
K40: Fechas | L40: ti | M40: N | N40: r | P40: ti | Q40: Δt | R40: N30/06/2010
K41: =K35 -> 40186 | L41: =L35 -> 2010.5861 | M41: =C14 -> 214298.24 | N41: =LN(M42/M41)/L43 -> 0.011851516 | P41: =P35 -> 2010.5 | Q41: =P41-L41 -> -0.086073059 | R41: =M41*EXP($N$41*Q41) -> 214079.74
K42: =K36 -> 43708 | L42: =L36 -> 2019.6683 | M42: =H14 -> 238652
...

Sheet Cuadro 1
A1: Cuadro 1
A2: Puebla: tablas abreviadas de mortalidad, 2010, mujeres
A4: x (edad) | B4: n | C4: nNx | D4: nDx | E4: nmx | F4: nax | G4: nqx | H4: npx | I4: lx | J4: ndx | K4: nLx | L4: Tx
A5: 0 | B5: 1 | C5: 52963 | D5: 1001 | E5: =D5/C5 -> 0.018899987 | F5: =0.053 + 2.8 * E5 -> 0.10591996 | G5: =(B5*E5)/(1+(B5-F5)*E5) -> 0.01858592 | H5: =1-G5 -> 0.98141408 | I5: 100000 | J5: =I5*G5 -> 1858.592 | K5: =(B5*I6)+(F5*J5) -> 98338.27 | L5: =K5+L6 -> 7650789.2 | M5: =L5/I5 -> 76.507892
A6: 1 | B6: 4 | C6: 54472 | D6: 189 | E6: =D6/C6 -> 0.0034696725 | F6: =1.522 - 1.518 * E5 -> 1.4933098 | G6: =(B6*E6)/(1+(B6-F6)*E6) -> 0.013759022 | H6: =1-G6 -> 0.98624098 | I6: =I5*H5 -> 98141.408 | J6: =I6*G6 -> 1350.3298 | K6: =(B6*I7)+(F6*J6) -> 389180.77 | L6: =K6+L7 -> 7552450.9 | M6: =L6/I6 -> 76.954785
A7: 5 | B7: 5 | C7: 306264 | D7: 80 | E7: =D7/C7 -> 0.00026121255 | F7: =B7/2 -> 2.5 | G7: =(B7*E7)/(1+(B7-F7)*E7) -> 0.0013052104 | H7: =1-G7 -> 0.99869479 | I7: =I6*H6 -> 96791.078 | J7: =I7*G7 -> 126.33272 | K7: =(B7*I8)+(F7*J7) -> 483639.56 | L7: =K7+L8 -> 7163270.1 | M7: =L7/I7 -> 74.007546
A8: 10 | B8: 5 | C8: 299188 | D8: 79 | E8: =D8/C8 -> 0.00026404802 | F8: =B8/2 -> 2.5 | G8: =(B8*E8)/(1+(B8-F8)*E8) -> 0.0013193692 | H8: =1-G8 -> 0.99868063 | I8: =I7*H7 -> 96664.745 | J8: =I8*G8 -> 127.53649 | K8: =(B8*I9)+(F8*J8) -> 483004.89 | L8: =K8+L9 -> 6679630.6 | M8: =L8/I8 -> 69.101
A9: 15 | B9: 5 | C9: 304996 | D9: 158 | E9: =D9/C9 -> 0.00051803958 | F9: =B9/2 -> 2.5 | G9: =(B9*E9)/(1+(B9-F9)*E9) -> 0.0025868477 | H9: =1-G9 -> 0.99741315 | I9: =I8*H8 -> 96537.209 | J9: =I9*G9 -> 249.72706 | K9: =(B9*I10)+(F9*J9) -> 482061.73 | L9: =K9+L10 -> 6196625.7 | M9: =L9/I9 -> 64.188987
A10: 20 | B10: 5 | C10: 270498 | D10: 127 | E10: =D10/C10 -> 0.0004695044 | F10: =B10/2 -> 2.5 | G10: =(B10*E10)/(1+(B10-F10)*E10) -> 0.0023447698 | H10: =1-G10 -> 0.99765523 | I10: =I9*H9 -> 96287.482 | J10: =I10*G10 -> 225.77198 | K10: =(B10*I11)+(F10*J10) -> 480872.98 | L10: =K10+L11 -> 5714564 | M10: =L10/I10 -> 59.348981
A11: 25 | B11: 5 | C11: 237932 | D11: 170 | E11: =D11/C11 -> 0.00071448985 | F11: =B11/2 -> 2.5 | G11: =(B11*E11)/(1+(B11-F11)*E11) -> 0.0035660795 | H11: =1-G11 -> 0.99643392 | I11: =I10*H10 -> 96061.71 | J11: =I11*G11 -> 342.56369 | K11: =(B11*I12)+(F11*J11) -> 479452.14 | L11: =K11+L12 -> 5233691 | M11: =L11/I11 -> 54.482592
A12: 30 | B12: 5 | C12: 227543 | D12: 182 | E12: =D12/C12 -> 0.00079984882 | F12: =B12/2 -> 2.5 | G12: =(B12*E12)/(1+(B12-F12)*E12) -> 0.0039912631 | H12: =1-G12 -> 0.99600874 | I12: =I11*H11 -> 95719.146 | J12: =I12*G12 -> 382.04029 | K12: =(B12*I13)+(F12*J12) -> 477640.63 | L12: =K12+L13 -> 4754238.8 | M12: =L12/I12 -> 49.66863
A13: 35 | B13: 5 | C13: 212271 | D13: 266 | E13: =D13/C13 -> 0.0012531151 | F13: =B13/2 -> 2.5 | G13: =(B13*E13)/(1+(B13-F13)*E13) -> 0.0062460082 | H13: =1-G13 -> 0.99375399 | I13: =I12*H12 -> 95337.106 | J13: =I13*G13 -> 595.47634 | K13: =(B13*I14)+(F13*J13) -> 475196.84 | L13: =K13+L14 -> 4276598.2 | M13: =L13/I13 -> 44.857647
A14: 40 | B14: 5 | C14: 177328 | D14: 315 | E14: =D14/C14 -> 0.0017763692 | F14: =B14/2 -> 2.5 | G14: =(B14*E14)/(1+(B14-F14)*E14) -> 0.0088425769 | H14: =1-G14 -> 0.99115742 | I14: =I13*H13 -> 94741.63 | J14: =I14*G14 -> 837.76014 | K14: =(B14*I15)+(F14*J14) -> 471613.75 | L14: =K14+L15 -> 3801401.4 | M14: =L14/I14 -> 40.123876
A15: 45 | B15: 5 | C15: 150117 | D15: 440 | E15: =D15/C15 -> 0.0029310471 | F15: =B15/2 -> 2.5 | G15: =(B15*E15)/(1+(B15-F15)*E15) -> 0.014548629 | H15: =1-G15 -> 0.98545137 | I15: =I14*H14 -> 93903.869 | J15: =I15*G15 -> 1366.1725 | K15: =(B15*I16)+(F15*J15) -> 466103.92 | L15: =K15+L16 -> 3329787.6 | M15: =L15/I15 -> 35.459536
A16: 50 | B16: 5 | C16: 129643 | D16: 647 | E16: =D16/C16 -> 0.0049906281 | F16: =B16/2 -> 2.5 | G16: =(B16*E16)/(1+(B16-F16)*E16) -> 0.024645647 | H16: =1-G16 -> 0.97535435 | I16: =I15*H15 -> 92537.697 | J16: =I16*G16 -> 2280.6514 | K16: =(B16*I17)+(F16*J16) -> 456986.86 | L16: =K16+L17 -> 2863683.7 | M16: =L16/I16 -> 30.946131
A17: 55 | B17: 5 | C17: 100712 | D17: 777 | E17: =D17/C17 -> 0.0077150687 | F17: =B17/2 -> 2.5 | G17: =(B17*E17)/(1+(B17-F17)*E17) -> 0.037845394 | H17: =1-G17 -> 0.96215461 | I17: =I16*H16 -> 90257.045 | J17: =I17*G17 -> 3415.8134 | K17: =(B17*I18)+(F17*J17) -> 442745.69 | L17: =K17+L18 -> 2406696.9 | M17: =L17/I17 -> 26.66492
A18: 60 | B18: 5 | C18: 81524 | D18: 925 | E18: =D18/C18 -> 0.011346352 | F18: =B18/2 -> 2.5 | G18: =(B18*E18)/(1+(B18-F18)*E18) -> 0.055166902 | H18: =1-G18 -> 0.9448331 | I18: =I17*H17 -> 86841.232 | J18: =I18*G18 -> 4790.7618 | K18: =(B18*I19)+(F18*J18) -> 422229.26 | L18: =K18+L19 -> 1963951.2 | M18: =L18/I18 -> 22.615423
... A22: 80 | B22: 5 | C22: 24398 | D22: 1740 | E22: =D22/C22 -> 0.071317321 | F22: =B22/2 -> 2.5 | G22: =(B22*E22)/(1+(B22-F22)*E22) -> 0.30262975 | H22: =1-G22 -> 0.69737025 | I22: =I21*H21 -> 53185.465 | J22: =I22*G22 -> 16095.504 | K22: =(B22*I23)+(F22*J22) -> 225688.56 | L22: =K22+L23 -> 493661.02 | M22: =L22/I22 -> 9.2818785
A23: 85+ | B23: 5 | C23: 23994 | D23: 3321 | E23: =D23/C23 -> 0.1384096 | F23: =B23/2 -> 2.5 | G23: 1 | H23: =1-G23 -> 0 | I23: =I22*H22 -> 37089.961 | J23: =I23*G23 -> 37089.961 | K23: =I23/E23 -> 267972.45 | L23: =I23/E23 -> 267972.45 | M23: =L23/I23 -> 7.2249322

Sheet Cuadro 2
A1: Cuadro 2
A2: Puebla: tablas abreviadas de mortalidad, 2019, mujeres
A4: x (edad) | B4: n | C4: nNx | D4: nDx | E4: nmx | F4: nax | G4: nqx | H4: npx | I4: lx | J4: ndx | K4: nLx | L4: Tx
A5: 0 | B5: 1 | C5: 61523 | D5: 689 | E5: =D5/C5 -> 0.011199064 | F5: =0.053 + 2.8 * E5 -> 0.084357379 | G5: =(B5*E5)/(1+(B5-F5)*E5) -> 0.01108539 | H5: =1-G5 -> 0.98891461 | I5: 100000 | J5: =I5*G5 -> 1108.539 | K5: =(B5*I6)+(F5*J5) -> 98984.974 | L5: =K5+L6 -> 7786572.1 | M5: =L5/I5 -> 77.865721
A6: 1 | B6: 4 | C6: 60517 | D6: 72 | E6: =D6/C6 -> 0.0011897483 | F6: =1.522 - 1.518 * E5 -> 1.5049998 | G6: =(B6*E6)/(1+(B6-F6)*E6) -> 0.0047449084 | H6: =1-G6 -> 0.99525509 | I6: =I5*H5 -> 98891.461 | J6: =I6*G6 -> 469.23093 | K6: =(B6*I7)+(F6*J6) -> 394395.11 | L6: =K6+L7 -> 7687587.1 | M6: =L6/I6 -> 77.737623
A7: 5 | B7: 5 | C7: 303890 | D7: 57 | E7: =D7/C7 -> 0.00018756787 | F7: =B7/2 -> 2.5 | G7: =(B7*E7)/(1+(B7-F7)*E7) -> 0.00093739978 | H7: =1-G7 -> 0.9990626 | I7: =I6*H6 -> 98422.23 | J7: =I7*G7 -> 92.260977 | K7: =(B7*I8)+(F7*J7) -> 491880.5 | L7: =K7+L8 -> 7293192 | M7: =L7/I7 -> 74.101065
A8: 10 | B8: 5 | C8: 311088 | D8: 73 | E8: =D8/C8 -> 0.00023466029 | F8: =B8/2 -> 2.5 | G8: =(B8*E8)/(1+(B8-F8)*E8) -> 0.0011726135 | H8: =1-G8 -> 0.99882739 | I8: =I7*H7 -> 98329.969 | J8: =I8*G8 -> 115.30305 | K8: =(B8*I9)+(F8*J8) -> 491361.59 | L8: =K8+L9 -> 6801311.5 | M8: =L8/I8 -> 69.168246
A9: 15 | B9: 5 | C9: 314520 | D9: 145 | E9: =D9/C9 -> 0.00046101997 | F9: =B9/2 -> 2.5 | G9: =(B9*E9)/(1+(B9-F9)*E9) -> 0.0023024462 | H9: =1-G9 -> 0.99769755 | I9: =I8*H8 -> 98214.666 | J9: =I9*G9 -> 226.13398 | K9: =(B9*I10)+(F9*J9) -> 490508 | L9: =K9+L10 -> 6309949.9 | M9: =L9/I9 -> 64.246514
A10: 20 | B10: 5 | C10: 305706 | D10: 154 | E10: =D10/C10 -> 0.00050375197 | F10: =B10/2 -> 2.5 | G10: =(B10*E10)/(1+(B10-F10)*E10) -> 0.0025155918 | H10: =1-G10 -> 0.99748441 | I10: =I9*H9 -> 97988.532 | J10: =I10*G10 -> 246.49914 | K10: =(B10*I11)+(F10*J10) -> 489326.41 | L10: =K10+L11 -> 5819441.9 | M10: =L10/I10 -> 59.38901
A11: 25 | B11: 5 | C11: 291099 | D11: 195 | E11: =D11/C11 -> 0.0006698752 | F11: =B11/2 -> 2.5 | G11: =(B11*E11)/(1+(B11-F11)*E11) -> 0.0033437762 | H11: =1-G11 -> 0.99665622 | I11: =I10*H10 -> 97742.033 | J11: =I11*G11 -> 326.82748 | K11: =(B11*I12)+(F11*J11) -> 487893.1 | L11: =K11+L12 -> 5330115.5 | M11: =L11/I11 -> 54.532481
A12: 30 | B12: 5 | C12: 262743 | D12: 207 | E12: =D12/C12 -> 0.00078784211 | F12: =B12/2 -> 2.5 | G12: =(B12*E12)/(1+(B12-F12)*E12) -> 0.0039314671 | H12: =1-G12 -> 0.99606853 | I12: =I11*H11 -> 97415.205 | J12: =I12*G12 -> 382.98468 | K12: =(B12*I13)+(F12*J12) -> 486118.57 | L12: =K12+L13 -> 4842222.4 | M12: =L12/I12 -> 49.707049
A13: 35 | B13: 5 | C13: 238652 | D13: 288 | E13: =D13/C13 -> 0.0012067781 | F13: =B13/2 -> 2.5 | G13: =(B13*E13)/(1+(B13-F13)*E13) -> 0.0060157412 | H13: =1-G13 -> 0.99398426 | I13: =I12*H12 -> 97032.221 | J13: =I13*G13 -> 583.72073 | K13: =(B13*I14)+(F13*J13) -> 483701.8 | L13: =K13+L14 -> 4356103.9 | M13: =L13/I13 -> 44.893375
A14: 40 | B14: 5 | C14: 221454 | D14: 437 | E14: =D14/C14 -> 0.0019733218 | F14: =B14/2 -> 2.5 | G14: =(B14*E14)/(1+(B14-F14)*E14) -> 0.0098181728 | H14: =1-G14 -> 0.99018183 | I14: =I13*H13 -> 96448.5 | J14: =I14*G14 -> 946.94804 | K14: =(B14*I15)+(F14*J14) -> 479875.13 | L14: =K14+L15 -> 3872402.1 | M14: =L14/I14 -> 40.149946
A15: 45 | B15: 5 | C15: 200458 | D15: 584 | E15: =D15/C15 -> 0.0029133285 | F15: =B15/2 -> 2.5 | G15: =(B15*E15)/(1+(B15-F15)*E15) -> 0.014461316 | H15: =1-G15 -> 0.98553868 | I15: =I14*H14 -> 95501.552 | J15: =I15*G15 -> 1381.0781 | K15: =(B15*I16)+(F15*J15) -> 474055.06 | L15: =K15+L16 -> 3392526.9 | M15: =L15/I15 -> 35.523265
A16: 50 | B16: 5 | C16: 169598 | D16: 780 | E16: =D16/C16 -> 0.0045991108 | F16: =B16/2 -> 2.5 | G16: =(B16*E16)/(1+(B16-F16)*E16) -> 0.022734162 | H16: =1-G16 -> 0.97726584 | I16: =I15*H15 -> 94120.474 | J16: =I16*G16 -> 2139.7501 | K16: =(B16*I17)+(F16*J16) -> 465252.99 | L16: =K16+L17 -> 2918471.9 | M16: =L16/I16 -> 31.007832
A17: 55 | B17: 5 | C17: 141335 | D17: 1070 | E17: =D17/C17 -> 0.0075706654 | F17: =B17/2 -> 2.5 | G17: =(B17*E17)/(1+(B17-F17)*E17) -> 0.037150198 | H17: =1-G17 -> 0.9628498 | I17: =I16*H16 -> 91980.724 | J17: =I17*G17 -> 3417.1021 | K17: =(B17*I18)+(F17*J17) -> 451360.86 | L17: =K17+L18 -> 2453218.9 | M17: =L17/I17 -> 26.671011
A18: 60 | B18: 5 | C18: 112369 | D18: 1286 | E18: =D18/C18 -> 0.011444438 | F18: =B18/2 -> 2.5 | G18: =(B18*E18)/(1+(B18-F18)*E18) -> 0.055630537 | H18: =1-G18 -> 0.94436946 | I18: =I17*H17 -> 88563.622 | J18: =I18*G18 -> 4926.8418 | K18: =(B18*I19)+(F18*J18) -> 430501 | L18: =K18+L19 -> 2001858 | M18: =L18/I18 -> 22.603615
... A22: 80 | B22: 5 | C22: 32500 | D22: 2289 | E22: =D22/C22 -> 0.070430769 | F22: =B22/2 -> 2.5 | G22: =(B22*E22)/(1+(B22-F22)*E22) -> 0.29943096 | H22: =1-G22 -> 0.70056904 | I22: =I21*H21 -> 55844.059 | J22: =I22*G22 -> 16721.44 | K22: =(B22*I23)+(F22*J22) -> 237416.69 | L22: =K22+L23 -> 502395.76 | M22: =L22/I22 -> 8.9964048
A23: 85+ | B23: 5 | C23: 30499 | D23: 4503 | E23: =D23/C23 -> 0.14764419 | F23: =B23/2 -> 2.5 | G23: 1 | H23: =1-G23 -> 0 | I23: =I22*H22 -> 39122.618 | J23: =I23*G23 -> 39122.618 | K23: =I23/E23 -> 264979.07 | L23: =I23/E23 -> 264979.07 | M23: =L23/I23 -> 6.7730402

Sheet TGF, TBR y TNR
A1: Puebla 2010 | I1: K
I2: =39110/80299 -> 0.48705463 | N2: =G27-G12 -> -1.5714538
A3: Edad | B3: Punto medio | C3: x | D3: x+n | E3: Nacimientos | F3: Población femenina 30/06/2010 | G3: f(x,5) | H3: % f(x,5) | I3: f(x,5) fem | J3: L(x) fem | K3: m+2,5P0 | L3: m+2,5P0 * f(x,5)fem
A4: 15-19 | B4: 17.5 | C4: 15 | D4: 19 | E4: 14203 | F4: 307908.78 | G4: =E4/F4 -> 0.046127297 | H4: =G4/$G$11 -> 0.14676632 | I4: =G4*$I$2 -> 0.022466514 | J4: ='Cuadro 1'!K9 -> 482061.73 | K4: =J4/(5*100000) -> 0.96412345 | L4: =K4*I4 -> 0.021660493
A5: 20-24 | B5: 22.5 | C5: 20 | D5: 24 | E5: 23995 | F5: 273081.32 | G5: =E5/F5 -> 0.0878676 | H5: =G5/$G$11 -> 0.27957424 | I5: =G5*$I$2 -> 0.042796321 | J5: ='Cuadro 1'!K10 -> 480872.98 | K5: =J5/(5*100000) -> 0.96174596 | L5: =K5*I5 -> 0.041159189
A6: 25-29 | B6: 27.5 | C6: 25 | D6: 29 | E6: 20094 | F6: 240204.31 | G6: =E6/F6 -> 0.083653787 | H6: =G6/$G$11 -> 0.26616687 | I6: =G6*$I$2 -> 0.040743965 | J6: ='Cuadro 1'!K11 -> 479452.14 | K6: =J6/(5*100000) -> 0.95890428 | L6: =K6*I6 -> 0.039069562
A7: 30-34 | B7: 32.5 | C7: 30 | D7: 34 | E7: 13457 | F7: 229716.09 | G7: =E7/F7 -> 0.058581008 | H7: =G7/$G$11 -> 0.18639113 | I7: =G7*$I$2 -> 0.028532151 | J7: ='Cuadro 1'!K12 -> 477640.63 | K7: =J7/(5*100000) -> 0.95528126 | L7: =K7*I7 -> 0.027256229
A8: 35-39 | B8: 37.5 | C8: 35 | D8: 39 | E8: 6257 | F8: 214298.24 | G8: =E8/F8 -> 0.029197627 | H8: =G8/$G$11 -> 0.09290005 | I8: =G8*$I$2 -> 0.014220839 | J8: ='Cuadro 1'!K13 -> 475196.84 | K8: =J8/(5*100000) -> 0.95039368 | L8: =K8*I8 -> 0.013515396
A9: 40-44 | B9: 42.5 | C9: 40 | D9: 44 | E9: 1432 | F9: 179021.52 | G9: =E9/F9 -> 0.0079990381 | H9: =G9/$G$11 -> 0.025451077 | I9: =G9*$I$2 -> 0.0038959686 | J9: ='Cuadro 1'!K14 -> 471613.75 | K9: =J9/(5*100000) -> 0.9432275 | L9: =K9*I9 -> 0.0036747847
A10: 45-49 | B10: 47.5 | C10: 45 | D10: 49 | E10: 131 | F10: 151550.65 | G10: =E10/F10 -> 0.00086439747 | H10: =G10/$G$11 -> 0.0027503115 | I10: =G10*$I$2 -> 0.00042100879 | J10: ='Cuadro 1'!K15 -> 466103.92 | K10: =J10/(5*100000) -> 0.93220783 | L10: =K10*I10 -> 0.00039246769
A11: Total | G11: =SUM(G4:G10) -> 0.31429075 | L11: =SUM(L4:L10) -> 0.14672812
F12: TGF | G12: =SUM(G4:G10)*5 -> 1.5714538
F13: TBR | I13: =G12*I2 -> 0.76538384 | K13: TBR (K obs) | L13: =G12*Puebla!Q8 -> 0.76538384
F14: TNR | L14: =L11*5 -> 0.73364061
A29: Puebla 2019 | I29: K
I30: =39110/80299 -> 0.48705463
A31: Edad | B31: Punto medio | C31: x | D31: x+n | E31: Nacimientos | F31: Población femenina 30/06/2010 | G31: f(x,5) | H31: % f(x,5) | I31: f(x,5) fem | J31: L(x) fem | K31: m+2,5P0 | L31: m+2,5P0 * f(x,5)fem
A32: 15-19 | B32: 17.5 | C32: 15 | D32: 19 | E32: 13554 | F32: 314520 | G32: =E32/F32 -> 0.043094239 | H32: =G32/$G$39 -> 0.15596044 | I32: =G32*$I$2 -> 0.020989249 | J32: ='Cuadro 2'!K9 -> 490508 | K32: =J32/(5*100000) -> 0.98101599 | L32: =K32*I32 -> 0.020590789
A33: 20-24 | B33: 22.5 | C33: 20 | D33: 24 | E33: 23299 | F33: 305706 | G33: =E33/F33 -> 0.076213748 | H33: =G33/$G$39 -> 0.27582179 | I33: =G33*$I$2 -> 0.037120259 | J33: ='Cuadro 1'!K10 -> 480872.98 | K33: =J33/(5*100000) -> 0.96174596 | L33: =K33*I33 -> 0.035700259
A34: 25-29 | B34: 27.5 | C34: 25 | D34: 29 | E34: 21073 | F34: 291099 | G34: =E34/F34 -> 0.07239118 | H34: =G34/$G$39 -> 0.2619877 | I34: =G34*$I$2 -> 0.035258459 | J34: ='Cuadro 1'!K11 -> 479452.14 | K34: =J34/(5*100000) -> 0.95890428 | L34: =K34*I34 -> 0.033809488
A35: 30-34 | B35: 32.5 | C35: 30 | D35: 34 | E35: 13413 | F35: 262743 | G35: =E35/F35 -> 0.051049885 | H35: =G35/$G$39 -> 0.18475237 | I35: =G35*$I$2 -> 0.024864083 | J35: ='Cuadro 1'!K12 -> 477640.63 | K35: =J35/(5*100000) -> 0.95528126 | L35: =K35*I35 -> 0.023752193
A36: 35-39 | B36: 37.5 | C36: 35 | D36: 39 | E36: 6282 | F36: 238652 | G36: =E36/F36 -> 0.026322847 | H36: =G36/$G$39 -> 0.095263844 | I36: =G36*$I$2 -> 0.012820664 | J36: ='Cuadro 1'!K13 -> 475196.84 | K36: =J36/(5*100000) -> 0.95039368 | L36: =K36*I36 -> 0.012184678
A37: 40-44 | B37: 42.5 | C37: 40 | D37: 44 | E37: 1498 | F37: 221454 | G37: =E37/F37 -> 0.0067643845 | H37: =G37/$G$39 -> 0.024480683 | I37: =G37*$I$2 -> 0.0032946248 | J37: ='Cuadro 1'!K14 -> 471613.75 | K37: =J37/(5*100000) -> 0.9432275 | L37: =K37*I37 -> 0.0031075807
A38: 45-49 | B38: 47.5 | C38: 45 | D38: 49 | E38: 96 | F38: 200458 | G38: =E38/F38 -> 0.00047890331 | H38: =G38/$G$39 -> 0.0017331777 | I38: =G38*$I$2 -> 0.00023325208 | J38: ='Cuadro 1'!K15 -> 466103.92 | K38: =J38/(5*100000) -> 0.93220783 | L38: =K38*I38 -> 0.00021743941
A39: Total | G39: =SUM(G32:G38) -> 0.27631519 | L39: =SUM(L32:L38) -> 0.12936243
F40: TGF | G40: =SUM(G32:G38)*5 -> 1.3815759
F41: TBR | I41: =G40*I30 -> 0.67290296 | K41: TBR (K obs) | L41: =G40*Puebla!Q8 -> 0.67290296
F42: TNR | L42: =L39*5 -> 0.64681213

Sheet Sheet1
B2: TNR
B3: Edad | C3: f(x,5) | E3: nLx | G3: nLx / (5*lo) | I3: f(x,5) * (nLx / (5*lo))
C4: Panamá | D4: Brasil | E4: Panamá | F4: Brasil | G4: Panamá | H4: Brasil | I4: Panamá | J4: Brasil
B5: 15-19 | C5: ='TGF, TBR y TNR'!G19 -> 0 | D5: ='TGF, TBR y TNR'!G4 -> 0.046127297 | E5: ='TGF, TBR y TNR'!J19 -> 0 | F5: ='TGF, TBR y TNR'!J4 -> 482061.73 | G5: ='TGF, TBR y TNR'!K19 -> 0 | H5: ='TGF, TBR y TNR'!K4 -> 0.96412345 | I5: ='TGF, TBR y TNR'!L19 -> 0 | J5: ='TGF, TBR y TNR'!L4 -> 0.021660493
B6: 20-24 | C6: ='TGF, TBR y TNR'!G20 -> 0 | D6: ='TGF, TBR y TNR'!G5 -> 0.0878676 | E6: ='TGF, TBR y TNR'!J20 -> 0 | F6: ='TGF, TBR y TNR'!J5 -> 480872.98 | G6: ='TGF, TBR y TNR'!K20 -> 0 | H6: ='TGF, TBR y TNR'!K5 -> 0.96174596 | I6: ='TGF, TBR y TNR'!L20 -> 0 | J6: ='TGF, TBR y TNR'!L5 -> 0.041159189
B7: 25-29 | C7: ='TGF, TBR y TNR'!G21 -> 0 | D7: ='TGF, TBR y TNR'!G6 -> 0.083653787 | E7: ='TGF, TBR y TNR'!J21 -> 0 | F7: ='TGF, TBR y TNR'!J6 -> 479452.14 | G7: ='TGF, TBR y TNR'!K21 -> 0 | H7: ='TGF, TBR y TNR'!K6 -> 0.95890428 | I7: ='TGF, TBR y TNR'!L21 -> 0 | J7: ='TGF, TBR y TNR'!L6 -> 0.039069562
B8: 30-34 | C8: ='TGF, TBR y TNR'!G22 -> 0 | D8: ='TGF, TBR y TNR'!G7 -> 0.058581008 | E8: ='TGF, TBR y TNR'!J22 -> 0 | F8: ='TGF, TBR y TNR'!J7 -> 477640.63 | G8: ='TGF, TBR y TNR'!K22 -> 0 | H8: ='TGF, TBR y TNR'!K7 -> 0.95528126 | I8: ='TGF, TBR y TNR'!L22 -> 0 | J8: ='TGF, TBR y TNR'!L7 -> 0.027256229
B9: 35-39 | C9: ='TGF, TBR y TNR'!G23 -> 0 | D9: ='TGF, TBR y TNR'!G8 -> 0.029197627 | E9: ='TGF, TBR y TNR'!J23 -> 0 | F9: ='TGF, TBR y TNR'!J8 -> 475196.84 | G9: ='TGF, TBR y TNR'!K23 -> 0 | H9: ='TGF, TBR y TNR'!K8 -> 0.95039368 | I9: ='TGF, TBR y TNR'!L23 -> 0 | J9: ='TGF, TBR y TNR'!L8 -> 0.013515396
B10: 40-44 | C10: ='TGF, TBR y TNR'!G24 -> 0 | D10: ='TGF, TBR y TNR'!G9 -> 0.0079990381 | E10: ='TGF, TBR y TNR'!J24 -> 0 | F10: ='TGF, TBR y TNR'!J9 -> 471613.75 | G10: ='TGF, TBR y TNR'!K24 -> 0 | H10: ='TGF, TBR y TNR'!K9 -> 0.9432275 | I10: ='TGF, TBR y TNR'!L24 -> 0 | J10: ='TGF, TBR y TNR'!L9 -> 0.0036747847
B11: 45-49 | C11: ='TGF, TBR y TNR'!G25 -> 0 | D11: ='TGF, TBR y TNR'!G10 -> 0.00086439747 | E11: ='TGF, TBR y TNR'!J25 -> 0 | F11: ='TGF, TBR y TNR'!J10 -> 466103.92 | G11: ='TGF, TBR y TNR'!K25 -> 0 | H11: ='TGF, TBR y TNR'!K10 -> 0.93220783 | I11: ='TGF, TBR y TNR'!L25 -> 0 | J11: ='TGF, TBR y TNR'!L10 -> 0.00039246769
H12: K | I12: =J12 -> 0.48705463 | J12: ='TGF, TBR y TNR'!I2 -> 0.48705463
H13: TNR | I13: ='TGF, TBR y TNR'!L29 -> 0 | J13: ='TGF, TBR y TNR'!L14 -> 0.73364061
